Workbook

Sheet arrecadacao-cnae.csv
A1: Ano | B1: Mês | C1: Seção - Sigla | D1: Seção - Nome | E1: II | F1: IE | G1: IPI | H1: IRPF | I1: IRPJ | J1: IRRF | K1: IOF | L1: ITR | M1: Cofins | N1: Pis/Pasep | O1: CSLL | P1: Cide | Q1: Contribuição Previdenciária | R1: CPSSS | S1: Pagamento Unificado | T1: Outras Receitas Administradas | U1: Receitas Não Administradas | V1: Receita por categoria
A2: 2016 | B2: Jan | C2: A | D2: Agricultura, pecuária, prod. florestal, pesca e aqüicultura | E2: 2742218.4 | G2: 893858.53 | I2: 1.466679e+08 | J2: 49347430 | K2: 609206.8 | L2: 2222251.2 | M2: 37609113 | N2: 8484832.3 | O2: 77514368 | P2: 142078.76 | Q2: 8008290.3 | S2: 41971216 | T2: 3377850.7 | U2: 1511240.8 | V2: =SUM(D2:U2) -> 3.8110185e+08
A3: 2016 | B3: Jan | C3: B | D3: Indústrias extrativas | E3: 42899800 | G3: 24953913 | I3: 5.1645329e+08 | J3: 1.6343076e+08 | K3: 1230716.9 | L3: 2391927.4 | M3: 1.2269115e+08 | N3: 25694934 | O3: 2.1236763e+08 | P3: 13041969 | Q3: 11200043 | S3: 1.6098893e+08 | T3: 1448689.6 | U3: 6.1349393e+08 | V3: =SUM(D3:U3) -> 1.9122877e+09
A4: 2016 | B4: Jan | C4: C | D4: Indústrias de transformação | E4: 1.633818e+09 | F4: 1040859.4 | G4: 2.8497574e+09 | H4: 9117.98 | I4: 3.01067e+09 | J4: 3.3597124e+09 | K4: 1.0916979e+08 | L4: 630487.68 | M4: 6.0305433e+09 | N4: 1.2957353e+09 | O4: 1.3251593e+09 | P4: 6.236158e+08 | Q4: 6.4679553e+08 | R4: 1263.79 | S4: 1.9515655e+09 | T4: 95494214 | U4: 2.4530954e+09 | V4: =SUM(D4:U4) -> 2.5386814e+10
A5: 2016 | B5: Jan | C5: D | D5: Eletricidade e gás | E5: 5328420 | G5: 2175445.3 | I5: 9.9531011e+08 | J5: 5.4759006e+08 | K5: 12592106 | L5: 920472.99 | M5: 1.3528601e+09 | N5: 2.9810464e+08 | O5: 4.2564565e+08 | P5: 2746902.3 | Q5: 680414.86 | S5: 1.790255e+08 | T5: 865732.36 | U5: 1646606 | V5: =SUM(D5:U5) -> 3.8254921e+09
A6: 2016 | B6: Jan | C6: E | D6: Água, esgoto, ativ. de gestão de resíduos e descontaminação | E6: 354256.59 | G6: 1432422.1 | I6: 53338128 | J6: 1.5767095e+08 | K6: 532902.88 | L6: 6683 | M6: 2.2304528e+08 | N6: 56909464 | O6: 26390888 | P6: 73401.7 | Q6: 7286865.9 | S6: 59672186 | T6: 515722.66 | U6: 714449.1 | V6: =SUM(D6:U6) -> 5.879436e+08
A7: 2016 | B7: Jan | C7: F | D7: Construção | E7: 6708438.3 | F7: 1800.34 | G7: 8721875.3 | H7: 1331.86 | I7: 7.6715573e+08 | J7: 3.5979902e+08 | K7: 10881136 | L7: 458637.75 | M7: 5.5188119e+08 | N7: 1.2098352e+08 | O7: 4.2622503e+08 | P7: 3033644.1 | Q7: 2.9982402e+08 | R7: 12076.64 | S7: 5.721135e+08 | T7: 12357326 | U7: 16864795 | V7: =SUM(D7:U7) -> 3.1570231e+09
A8: 2016 | B8: Jan | C8: G | D8: Comércio; reparação de veículos automotores e motocicletas | E8: 1.0564002e+09 | F8: 491131.59 | G8: 8.6970277e+08 | H8: 15712.59 | I8: 2.3217215e+09 | J8: 1.3678164e+09 | K8: 7167852.7 | L8: 89055.07 | M8: 2.9177562e+09 | N8: 6.4278516e+08 | O8: 1.2842758e+09 | P8: 30306493 | Q8: 1.322745e+08 | S8: 3.5166416e+09 | T8: 94276861 | U8: 34201896 | V8: =SUM(D8:U8) -> 1.4275923e+10
A9: 2016 | B9: Jan | C9: H | D9: Transporte, armazenagem e correio | E9: 56100798 | G9: 10526693 | H9: 307.59 | I9: 8.3377973e+08 | J9: 6.12625e+08 | K9: 2475484.9 | L9: 49102.04 | M9: 6.3751029e+08 | N9: 1.3890502e+08 | O9: 3.7317434e+08 | P9: 10950780 | Q9: 2.8145633e+08 | R9: 49129.56 | S9: 4.8383206e+08 | T9: 15266710 | U9: 7219470.9 | V9: =SUM(D9:U9) -> 3.4639212e+09
A10: 2016 | B10: Jan | C10: I | D10: Alojamento e alimentação | E10: 613007.87 | G10: 221694.34 | H10: 2425.78 | I10: 1.3956972e+08 | J10: 73619591 | K10: 769367.67 | L10: 15454.36 | M10: 1.6648469e+08 | N10: 36578651 | O10: 70414539 | P10: 3583875.6 | Q10: 28073362 | R10: 16.47 | S10: 5.2158148e+08 | T10: 4149892.8 | U10: 3030316.7 | V10: =SUM(D10:U10) -> 1.0487081e+09
A11: 2016 | B11: Jan | C11: IN | D11: Inválido | E11: 5139.72 | H11: 5719.92 | I11: 131220.44 | J11: 195401.51 | L11: 5372.99 | M11: 70366.72 | N11: 23124.81 | O11: 106449.67 | Q11: 19968.21 | R11: 1392.11 | S11: 16591035 | T11: 10582838 | U11: 55950.21 | V11: =SUM(D11:U11) -> 27793979
A12: 2016 | B12: Jan | C12: J | D12: Informação e comunicação | E12: 23856720 | G12: 36207344 | H12: 1165.39 | I12: 5.7926755e+08 | J12: 1.1939505e+09 | K12: 9286893.7 | L12: 2519.24 | M12: 7.8432682e+08 | N12: 1.5705517e+08 | O12: 2.9236206e+08 | P12: 40414245 | Q12: 2.3764917e+08 | R12: 21.98 | S12: 3.5162306e+08 | T12: 32338208 | U12: 5609782.3 | V12: =SUM(D12:U12) -> 3.7439513e+09
A13: 2016 | B13: Jan | C13: K | D13: Atividades financeiras, de seguros e serviços relacionados | E13: 3629633.8 | G13: 2402099.8 | I13: 8.1313824e+09 | J13: 6.8283517e+09 | K13: 2.9546121e+09 | L13: 479060.72 | M13: 2.3625296e+09 | N13: 3.6664159e+08 | O13: 5.4225983e+09 | P13: 21982385 | Q13: 11688545 | R13: 41847858 | S13: 6.3733177e+08 | T13: 5.5446325e+08 | U13: 6588846.6 | V13: =SUM(D13:U13) -> 2.7346529e+10
A14: 2016 | B14: Jan | C14: L | D14: Atividades imobiliárias | E14: 331529.17 | G14: 20118.9 | I14: 6.6584559e+08 | J14: 74455863 | K14: 1672259.9 | L14: 450575.34 | M14: 2.0531379e+08 | N14: 44709123 | O14: 3.2964191e+08 | P14: 35262.11 | Q14: 3584805.5 | S14: 71035089 | T14: 3033452.1 | U14: 3134463.8 | V14: =SUM(D14:U14) -> 1.4032638e+09
A15: 2016 | B15: Jan | C15: M | D15: Atividades profissionais, científicas e técnicas | E15: 38284734 | G15: 21533714 | H15: 1154.34 | I15: 1.2424612e+09 | J15: 6.306072e+08 | K15: 5165999.7 | L15: 48191.63 | M15: 3.7240562e+08 | N15: 83173739 | O15: 5.3689892e+08 | P15: 31406356 | Q15: 42895395 | R15: 6782716.7 | S15: 4.2184803e+08 | T15: 7194547.8 | U15: 5052718.4 | V15: =SUM(D15:U15) -> 3.4457603e+09
A16: 2016 | B16: Jan | C16: N | D16: Atividades administrativas e serviços complementares | E16: 88732198 | F16: 372.98 | G16: 2.0207424e+08 | H16: 194.61 | I16: 7.0739833e+08 | J16: 4.4049174e+08 | K16: 2685453.2 | L16: 118506.42 | M16: 6.6773522e+08 | N16: 1.6532218e+08 | O16: 3.5296505e+08 | P16: 13797594 | Q16: 94700392 | R16: 86.31 | S16: 5.4635965e+08 | T16: 9767316.3 | U16: 9712620.5 | V16: =SUM(D16:U16) -> 3.3018611e+09
A17: 2016 | B17: Jan | C17: NI | D17: Não informado | E17: 127.72 | G17: 5119.19 | I17: 44266.64 | J17: 141290.59 | L17: 1249.17 | M17: 35654.14 | N17: 5818.3 | O17: 15871.15 | Q17: 225964.34 | S17: 162471.24 | T17: 10377.65 | U17: 90192.84 | V17: =SUM(D17:U17) -> 738402.97
A18: 2016 | B18: Jan | C18: O | D18: Administração pública, defesa e seguridade social | E18: 42386.13 | G18: 305635.37 | H18: 5092.26 | I18: 4736508 | J18: 1.8783376e+09 | K18: 74763.64 | L18: 57903.8 | M18: 23300772 | N18: 1.04829e+09 | O18: 2179235.4 | P18: 149454.48 | Q18: 39385482 | R18: 1.6910979e+09 | S18: 3.3336273e+08 | T18: 68813763 | U18: 2.0163918e+09 | V18: =SUM(D18:U18) -> 7.106531e+09
A19: 2016 | B19: Jan | C19: P | D19: Educação | E19: 268212.53 | G19: 341565.94 | I19: 82476213 | J19: 8.7601945e+08 | K19: 326829.33 | L19: 8866.93 | M19: 42712767 | N19: 54235409 | O19: 35796496 | P19: 137814.5 | Q19: 20831863 | R19: 5.4280256e+08 | S19: 2.8487539e+08 | T19: 3061911.2 | U19: 2486185.1 | V19: =SUM(D19:U19) -> 1.9463815e+09
A20: 2016 | B20: Jan | C20: PF | D20: Pessoa Física | E20: 11982139 | F20: 2326.81 | G20: 991903.97 | H20: 1.9630455e+09 | I20: 215214.19 | J20: 92078403 | K20: 245007.24 | L20: 11925244 | M20: 2219346.6 | N20: 549683.36 | O20: 85736.33 | P20: 62020.38 | Q20: 4.4645766e+08 | R20: 4685865.4 | S20: 62455356 | T20: 24047966 | U20: 33506947 | V20: =SUM(D20:U20) -> 2.6545563e+09
A21: 2016 | B21: Jan | C21: Q | D21: Saúde humana e serviços sociais | E21: 962836.82 | G21: 684443.1 | H21: 11164.95 | I21: 5.2398597e+08 | J21: 4.8105058e+08 | K21: 146768.22 | L21: 5423.78 | M21: 1.7455241e+08 | N21: 69932329 | O21: 2.5319592e+08 | P21: 709512.07 | Q21: 19235720 | R21: 9735506.3 | S21: 2.5575771e+08 | T21: 12737966 | U21: 3209334.8 | V21: =SUM(D21:U21) -> 1.8059136e+09
A22: 2016 | B22: Jan | C22: R | D22: Artes, cultura, esporte e recreação | E22: 302892.61 | G22: 186660.03 | I22: 44782564 | J22: 70650180 | K22: 114208.66 | L22: 5766.74 | M22: 23623665 | N22: 9260870.8 | O22: 21861366 | P22: 51866.77 | Q22: 4262822.4 | R22: 730908.08 | S22: 68616112 | T22: 1104244.9 | U22: 1093912.3 | V22: =SUM(D22:U22) -> 2.4664804e+08
A23: 2016 | B23: Jan | C23: S | D23: Outras atividades de serviços | E23: 2378619.6 | G23: 2507786.7 | I23: 26169538 | J23: 2.7012208e+08 | K23: 187239.52 | L23: 27647.69 | M23: 49418974 | N23: 26535892 | O23: 12286601 | P23: 1623694.1 | Q23: 9972171.1 | R23: 3002197.9 | S23: 1.7326215e+08 | T23: 5437160.8 | U23: 3226731.6 | V23: =SUM(D23:U23) -> 5.8615848e+08
A24: 2016 | B24: Jan | C24: T | D24: Serviços domésticos | I24: 1054.42 | J24: 33726.66 | M24: 23157.27 | N24: 5142.76 | O24: 793.76 | Q24: 156.25 | S24: 793655.49 | T24: 775 | U24: 381.26 | V24: =SUM(D24:U24) -> 858842.87
A25: 2016 | B25: Jan | C25: U | D25: Organismos internac. e outras instituições extraterritoriais | E25: 35967.61 | G25: 6534.39 | J25: 46246.52 | M25: 1681.26 | N25: 13474.44 | Q25: 347.3 | S25: 29721.33 | T25: 1049.22 | V25: =SUM(D25:U25) -> 135022.07
A26: 2016 | B26: Fev | C26: A | D26: Agricultura, pecuária, prod. florestal, pesca e aqüicultura | E26: 2213080 | G26: 433207.11 | I26: 27466504 | J26: 27269350 | K26: 552689.97 | L26: 2228377.1 | M26: 26494542 | N26: 6149525.3 | O26: 14510819 | P26: 124924.56 | Q26: 7485957.9 | S26: 35991083 | T26: 2740481.6 | U26: 3371842.9 | V26: =SUM(D26:U26) -> 1.5703238e+08
A27: 2016 | B27: Fev | C27: B | D27: Indústrias extrativas | E27: 28846650 | G27: 17998984 | I27: 62759995 | J27: 1.1958623e+08 | K27: 538305.2 | L27: 128401.68 | M27: 1.1717953e+08 | N27: 24518504 | O27: 59010312 | P27: 6153544 | Q27: 5621300.5 | S27: 1.5499602e+08 | T27: 5438005.2 | U27: 2.2412864e+08 | V27: =SUM(D27:U27) -> 8.2690442e+08
A28: 2016 | B28: Fev | C28: C | D28: Indústrias de transformação | E28: 1.4636244e+09 | F28: 1977674.3 | G28: 2.198268e+09 | H28: 1421.03 | I28: 8.193483e+08 | J28: 1.6641395e+09 | K28: 21187507 | L28: 1677384.8 | M28: 5.1321103e+09 | N28: 1.1017329e+09 | O28: 5.6839356e+08 | P28: 5.110214e+08 | Q28: 4.4951651e+08 | R28: 1729.81 | S28: 1.6957821e+09 | T28: 94588725 | U28: 7.6482644e+08 | V28: =SUM(D28:U28) -> 1.6488198e+10
A29: 2016 | B29: Fev | C29: D | D29: Eletricidade e gás | E29: 7072765.6 | G29: 2991316.7 | I29: 2.4502073e+08 | J29: 1.9885679e+08 | K29: 3542392.7 | L29: 548483.62 | M29: 1.210431e+09 | N29: 2.4545772e+08 | O29: 1.3854135e+08 | P29: 3325991.6 | Q29: 644453.73 | S29: 1.7460019e+08 | T29: 485598.16 | U29: 4652053 | V29: =SUM(D29:U29) -> 2.2361708e+09
A30: 2016 | B30: Fev | C30: E | D30: Água, esgoto, ativ. de gestão de resíduos e descontaminação | E30: 858423.38 | G30: 2460089.2 | I30: 1.0456145e+08 | J30: 69242683 | K30: 186419.77 | L30: 5470.36 | M30: 2.1455604e+08 | N30: 54365248 | O30: 54167169 | P30: 44858.88 | Q30: 5776970.2 | S30: 47450497 | T30: 257980.64 | U30: 1677863.9 | V30: =SUM(D30:U30) -> 5.5561117e+08
A31: 2016 | B31: Fev | C31: F | D31: Construção | E31: 7113279.3 | G31: 4338565.2 | H31: 594.89 | I31: 1.8747002e+08 | J31: 2.2901782e+08 | K31: 3299152.8 | L31: 337949.88 | M31: 3.8068935e+08 | N31: 84436371 | O31: 93761619 | P31: 2816974.6 | Q31: 2.1508459e+08 | R31: 12014.08 | S31: 4.4861438e+08 | T31: 8012551.6 | U31: 18800520 | V31: =SUM(D31:U31) -> 1.6838057e+09
A32: 2016 | B32: Fev | C32: G | D32: Comércio; reparação de veículos automotores e motocicletas | E32: 1.0070737e+09 | F32: 407012.07 | G32: 6.9117813e+08 | H32: 52398.5 | I32: 9.6263669e+08 | J32: 8.7612798e+08 | K32: 8696021.1 | L32: 372035.14 | M32: 2.4791448e+09 | N32: 5.3582549e+08 | O32: 4.876529e+08 | P32: 34623219 | Q32: 1.0105392e+08 | R32: 377.55 | S32: 2.6817272e+09 | T32: 1.1165254e+08 | U32: 38901949 | V32: =SUM(D32:U32) -> 1.0017126e+10
A33: 2016 | B33: Fev | C33: H | D33: Transporte, armazenagem e correio | E33: 43913566 | G33: 8466340 | I33: 2.848982e+08 | J33: 3.3629323e+08 | K33: 1226905.9 | L33: 278367.43 | M33: 5.5519802e+08 | N33: 1.2301075e+08 | O33: 1.2248662e+08 | P33: 8560502.7 | Q33: 2.5255394e+08 | R33: 91542.7 | S33: 4.1203961e+08 | T33: 42962616 | U33: 6593088.3 | V33: =SUM(D33:U33) -> 2.1985733e+09
A34: 2016 | B34: Fev | C34: I | D34: Alojamento e alimentação | E34: 431323.18 | G34: 214382.28 | I34: 67373375 | J34: 48262019 | K34: 258674.84 | L34: 37834.69 | M34: 1.517552e+08 | N34: 33429152 | O34: 33651153 | P34: 3229933.7 | Q34: 23516766 | S34: 4.9054651e+08 | T34: 2522054.2 | U34: 3884355.3 | V34: =SUM(D34:U34) -> 8.5911273e+08
A35: 2016 | B35: Fev | C35: IN | D35: Inválido | E35: 839.83 | H35: 7798.85 | I35: 19767.53 | J35: 124415.45 | L35: 1220.33 | M35: 46042.93 | N35: 21183.44 | O35: 5485.31 | P35: 2092.09 | Q35: 9859 | S35: 638255.75 | T35: 13660.38 | U35: 36767.95 | V35: =SUM(D35:U35) -> 927388.84
A36: 2016 | B36: Fev | C36: J | D36: Informação e comunicação | E36: 20280855 | G36: 26801687 | H36: 483.73 | I36: 3.3811655e+08 | J36: 7.4307239e+08 | K36: 7279126.2 | L36: 171.53 | M36: 6.8750779e+08 | N36: 1.3566389e+08 | O36: 1.8960316e+08 | P36: 36000773 | Q36: 1.7408269e+08 | S36: 3.0529752e+08 | T36: 18451844 | U36: 4537268.6 | V36: =SUM(D36:U36) -> 2.6866962e+09
A37: 2016 | B37: Fev | C37: K | D37: Atividades financeiras, de seguros e serviços relacionados | E37: 3125517 | G37: 1588272.5 | I37: 1.4981098e+09 | J37: 4.5752007e+09 | K37: 2.5916537e+09 | L37: 241805.15 | M37: 1.4398413e+09 | N37: 2.494992e+08 | O37: 1.0491373e+09 | P37: 27366189 | Q37: 10687272 | R37: 40453280 | S37: 5.7623989e+08 | T37: 3.420617e+08 | U37: 10017676 | V37: =SUM(D37:U37) -> 1.2415224e+10
A38: 2016 | B38: Fev | C38: L | D38: Atividades imobiliárias | E38: 67269.58 | G38: 21628.81 | H38: 1141.33 | I38: 95526697 | J38: 33706302 | K38: 1969135.4 | L38: 290774.43 | M38: 1.6201432e+08 | N38: 35357833 | O38: 46822620 | P38: 85625.12 | Q38: 3942235 | R38: 16.89 | S38: 62972344 | T38: 3050582.6 | U38: 2472410.7 | V38: =SUM(D38:U38) -> 4.4830093e+08
A39: 2016 | B39: Fev | C39: M | D39: Atividades profissionais, científicas e técnicas | E39: 28604041 | G39: 21424388 | H39: 2888.52 | I39: 2.8990728e+08 | J39: 3.3502926e+08 | K39: 3877280.4 | L39: 34590.78 | M39: 2.387827e+08 | N39: 54284484 | O39: 1.1263058e+08 | P39: 25700723 | Q39: 31717813 | R39: 18724251 | S39: 3.1066625e+08 | T39: 9901470.9 | U39: 4684911.5 | V39: =SUM(D39:U39) -> 1.4859729e+09
A40: 2016 | B40: Fev | C40: N | D40: Atividades administrativas e serviços complementares | E40: 70829165 | G40: 1.7926423e+08 | H40: 7891.77 | I40: 2.7648674e+08 | J40: 2.9602516e+08 | K40: 2232348.2 | L40: 94949 | M40: 5.6155188e+08 | N40: 1.3084444e+08 | O40: 1.180254e+08 | P40: 16082776 | Q40: 85361290 | R40: 33.93 | S40: 4.6622417e+08 | T40: 7090216.7 | U40: 9862784.9 | V40: =SUM(D40:U40) -> 2.2199835e+09
...

Sheet arrecadacao_total
A1: Ano | B1: Mês | C1: Receita
A2: 2016 | B2: Jan | C2: =SUMIFS('arrecadacao-cnae.csv'!V:V,'arrecadacao-cnae.csv'!A:A,A2,'arrecadacao-cnae.csv'!B:B,B2) -> 107656295463
A3: 2016 | B3: Fev | C3: =SUMIFS('arrecadacao-cnae.csv'!V:V,'arrecadacao-cnae.csv'!A:A,A3,'arrecadacao-cnae.csv'!B:B,B3) -> 65869818864
A4: 2016 | B4: Mar | C4: =SUMIFS('arrecadacao-cnae.csv'!V:V,'arrecadacao-cnae.csv'!A:A,A4,'arrecadacao-cnae.csv'!B:B,B4) -> 73329607179
A5: 2016 | B5: Abr | C5: =SUMIFS('arrecadacao-cnae.csv'!V:V,'arrecadacao-cnae.csv'!A:A,A5,'arrecadacao-cnae.csv'!B:B,B5) -> 89846835511
A6: 2016 | B6: Mai | C6: =SUMIFS('arrecadacao-cnae.csv'!V:V,'arrecadacao-cnae.csv'!A:A,A6,'arrecadacao-cnae.csv'!B:B,B6) -> 71866121668
A7: 2016 | B7: Jun | C7: =SUMIFS('arrecadacao-cnae.csv'!V:V,'arrecadacao-cnae.csv'!A:A,A7,'arrecadacao-cnae.csv'!B:B,B7) -> 74942546716
A8: 2016 | B8: Jul | C8: =SUMIFS('arrecadacao-cnae.csv'!V:V,'arrecadacao-cnae.csv'!A:A,A8,'arrecadacao-cnae.csv'!B:B,B8) -> 84324113669
A9: 2016 | B9: Ago | C9: =SUMIFS('arrecadacao-cnae.csv'!V:V,'arrecadacao-cnae.csv'!A:A,A9,'arrecadacao-cnae.csv'!B:B,B9) -> 68397503440
A10: 2016 | B10: Set | C10: =SUMIFS('arrecadacao-cnae.csv'!V:V,'arrecadacao-cnae.csv'!A:A,A10,'arrecadacao-cnae.csv'!B:B,B10) -> 72049585159
A11: 2016 | B11: Out | C11: =SUMIFS('arrecadacao-cnae.csv'!V:V,'arrecadacao-cnae.csv'!A:A,A11,'arrecadacao-cnae.csv'!B:B,B11) -> 125805386481
A12: 2016 | B12: Nov | C12: =SUMIFS('arrecadacao-cnae.csv'!V:V,'arrecadacao-cnae.csv'!A:A,A12,'arrecadacao-cnae.csv'!B:B,B12) -> 78465300932
A13: 2016 | B13: Dez | C13: =SUMIFS('arrecadacao-cnae.csv'!V:V,'arrecadacao-cnae.csv'!A:A,A13,'arrecadacao-cnae.csv'!B:B,B13) -> 86814973032
... A116: 2025 | B116: Jul | C116: =SUMIFS('arrecadacao-cnae.csv'!V:V,'arrecadacao-cnae.csv'!A:A,A116,'arrecadacao-cnae.csv'!B:B,B116) -> 252868605755
